Workbook
Name Address: Followup!$H$2:$H$400
Name Applicable: Startup!$O$2:$O$5
Name Apprenticable: 'Base Bid'!$F$13
Name Are_they_part_of_an_AFL_CIO_Affiliated_Union?: Followup!$AH$2:$AH$400
Name Average_no_people: 'Base Bid'!$H$7
Name Base_rate_total: 'VRF and Lists'!$F$2
Name Base_Rate_Wage: 'VRF and Lists'!$F$4
Name Bid?: 'Base Bid'!#REF!
Name Bid_All: 'Base Bid'!#REF!
Name Bid_Call_for_Pricing: 'Base Bid'!#REF!
Name Bid_Clerk: 'Base Bid'!$AB$4:$AB$7
Name Bid_Ductwork?: 'Base Bid'!#REF!
Name Bid_Percentage: 'Base Bid'!#REF!
Name Bid_Piping?: 'Base Bid'!#REF!
Name Bidding_company: 'VRF and Lists'!$S$2:$S$7
Name Breakout?: 'Base Bid'!#REF!
Name Captain: 'Base Bid'!$AA$4:$AA$7
Name CBA_Fringe: 'VRF and Lists'!$F$3
Name Check_Weekly?: Followup!$AM$2:$AM$400
Name Child_Companies: Followup!$AN$2:$AN$400
Name Citizen: 'Base Bid'!$F$12
Name City: Followup!$I$2:$I$400
Name Closing_Ratio: Followup!$N$2:$N$400
Name Code: 'Quantites and Price from Mike'!$D$4:$D$117
Name Company: Followup!$C$2:$C$400
Name Company_ID: Followup!$A$2:$A$400
Name Company_Selected: 'Base Bid'!#REF!
Name Company_Status: Followup!$M$2:$M$400
Name Company_Type: Followup!$B$2:$B$400
Name Contact: Followup!$E$2:$E$400
Name Country: Followup!$P$2:$P$400
Name Days_Per_Week: 'Base Bid'!$F$5
Name DCB: Startup!$M$5
Name Do_we_bid_both_piping_and_duct_to_them?: Followup!$AG$2:$AG$400
Name Do_we_bid_to_them?: Followup!$U$2:$U$400
Name Do_we_make_them_call_for_pricing_as_we_get_no_feedback?: Followup!$Z$2:$Z$400
Name Do_we_only_bid_ductwork_to_them?: Followup!$Y$2:$Y$400
Name Do_we_only_bid_piping_to_them?: Followup!$X$2:$X$400
Name Do_we_release_breakouts_to_them?: Followup!$V$2:$V$400
Name Domain: Startup!$N$2:$N$5
Name Duct_1: 'Base Bid'!$AC$4:$AC$7
Name Duct_2: 'Base Bid'!$AD$4:$AD$7
Name Duct_breakout_no_Quantities: 'Quantites and Price from Mike'!$F$74
Name Duct_breakout_with_Quantities: 'Quantites and Price from Mike'!$G$74
Name Duct_breakout_with_Quantities_END: 'Quantites and Price from Mike'!$H$74
Name DUCT_Code: 'Quantites and Price from Mike'!$D$77:$D$100
Name Duct_Cost_by_System: 'Quantites and Price from Mike'!$E$77:$E$100
Name Duct_Price: 'Quantites and Price from Mike'!$E$74
Name DUCT_Qnt: 'Quantites and Price from Mike'!$A$77:$A$100
Name DUCT_SYSTEM: 'Quantites and Price from Mike'!$F$77:$F$100
Name DUCT_System_Name: 'Quantites and Price from Mike'!$H$77:$H$100
Name DUCT_System_Name_NO_Release: 'Quantites and Price from Mike'!$I$77:$I$100
Name DUCT_System_Name_Release_qnt: 'Quantites and Price from Mike'!$J$77:$J$100
Name DUCT_Unit: 'Quantites and Price from Mike'!$G$77:$G$100
Name Email: Followup!$F$2:$F$400
Name EQUIPMENT_Code: 'Quantites and Price from Mike'!$D$104:$D$117
Name EQUIPMENT_Cost_by_System: 'Quantites and Price from Mike'!$E$104:$E$117
Name Equipment_Price: 'Quantites and Price from Mike'!$E$101
Name EQUIPMENT_Qnt: 'Quantites and Price from Mike'!$A$104:$A$117
Name EQUIPMENT_SYSTEM: 'Quantites and Price from Mike'!$F$104:$F$117

Sheet Startup
A1: Company | B1: Delaware Cornerstone Builders, Inc. | E1: PROJECT START UP SHEET | M1: Company | N1: Domain | O1: Applicable
A2: Job Name: | E2: Job No. | M2: ----- | N2: ----- | O2: -----
A3: Mechanical Contractor (Who we have contract with) | E3: Contract Type | G3: Prime Contractor | H3: Checkbox Prime | I3: FALSE | M3: Goel Services, Inc. | N3: goelservices.com | O3: Applicable
A4: Contractor | G4: Subcontractor | H4: Checkbox Subcontractor | I4: FALSE | M4: Goel DC, LLC | N4: goeldc.com | O4: Not applicable
A5: Address 1 | E5: Form of Contract (provide copy with Startup) | M5: Delaware Cornerstone Builders, Inc. | N5: dcbuilders.com
A6: Address 2 | F6: Purchase order | H6: Checkbox PO | I6: FALSE
A7: City, State, Zip | F7: Subcontract/Contract | H7: Checkbox Subcontract | I7: FALSE
A8: Office Phone | F8: Verbal | H8: Checkbox Verbal | I8: FALSE
A9: Fax | F9: Email | H9: Checkbox Email | I9: FALSE
A10: Client Contact | F10: Other | H10: Checkbox Other | I10: FALSE
A11: Email | E11: Budget
A12: Client Phone | E12: Contract Price
A13: Send Bills to (Name) | E13: In House /Temp Labor | H13: =+F13/F12 -> #DIV/0!
A14: Email to: | E14: Material Budget | H14: =+F14/F12 -> #DIV/0!
A15: Phone # | E15: Equipment Budget | H15: Checkbox Mech Bond Yes | I15: FALSE
A16: Are they Bonded | B16: YES NO | E16: Bond Cost | H16: Checkbox Mech Bond No | I16: FALSE
A17: Sureties Name | E17: OTH/Sub Budget | H17: Bonded? | I17: =IF(F16>0,TRUE,FALSE) -> FALSE
A18: Contractor (Who mechanical has contract with) | E18: Cost Estimate | F18: =SUM(F13:G17) -> 0 | H18: 0.85 | I18: Be Conservative
E19: Average Labor Rate | F19: =+F13/F20 -> #DIV/0! | H19: Checkbox - 2nd or 3rd tier | I19: TRUE | J19: Add 5% for markup if subcontracting to Goel
A20: Contractor | E20: Labor Manhours | H20: =+F14/F13 -> #DIV/0! | I20: =1/H20 -> #DIV/0!
A21: Address 1 | E21: Projected Start Date
A22: Address 2 | E22: Projected End Date | H22: =+F22-F21 -> 0 | I22: =ROUND(+H22/365*2000,-1) -> 0
A23: City, State, Zip | F23: Is Labor to be subcontracted to Goel Services? | H23: Is Labor to be sucontracted to Goel | I23: FALSE
A24: Office Phone | E24: Owner Information
A25: Fax | E25: Prime Contract # | K25: 1000
A26: Client Contact | B26: =IF(I$19=TRUE,"n/a","") -> n/a | E26: Owner Name
A27: Email | B27: =IF(I$19=TRUE,"n/a","") -> n/a | E27: Address
A28: Client Phone | B28: =IF(I$19=TRUE,"n/a","") -> n/a | E28: Address
A29: Prime Contractor | E29: City, State, Zip
A30: Contractor | E30: Phone
A31: Address | E31: Fax
A32: Address | E32: Client Contact
A33: City, State, Zip | E33: Email
A34: Phone | E34: Client Phone
A35: Fax | E35: Certified Payroll
A36: Client Contact/PM | F36: Yes - Include CP Wage Decision # and copy with startup | H36: Checkbox CP Yes | I36: FALSE
A37: Email | E37: Wage Decision #
A38: Client Phone | F38: No | H38: Checkbox CP No | I38: FALSE
A39: Are they Bonded | B39: YES NO | E39: Wage (Excluding Fringe)
A40: Sureties Name | E40: Fringe (min fringe = $3.93)
...

Sheet Base Bid
A1: BID Estimate # | B1: IDC6098 | C1: Bid Name | D1: SCU Replacement Basement to 6th Floor, East & West | F1: Team | G1: MIKE Estimate | H1: =+H48 -> 43837.68 | I1: PJ Estimate | J1: =PJ_Estimate -> 47600
A2: Bid Date | B2: 46141 | C2: Company Bidding | D2: Goel Services, Inc. | F2: Bil Shams | G2: Cost per Hr | H2: =+I48 -> 89.906848 | I2: Cost per Hr | J2: =+I47 -> 97.62
A3: Captain | B3: Bid Clerk | C3: Assistant Estimator | D3: Margin | E3: Hours and Wages (do not correct till you add MIKE info) | G3: PLA | H3: No | I3: Lifts | M3: Wage | Z3: Team | AA3: Captain | AB3: Bid Clerk | AC3: Duct 1 | AD3: Duct 2 | AE3: Hydronic 1 | AF3: Hydronic 2 | AG3: Plumbing 1 | AH3: Plumbing 2
A4: =_xlfn.XLOOKUP(F$2,Team_list,Captain) -> Bil Shams | B4: John Alex Lopez | C4: =_xlfn.XLOOKUP(F$2,Team_list,Bid_Clerk) -> Mark Tan | D4: 0.25 | E4: Hours per day | F4: 8 | G4: Category | H4: ---- | I4: Lifts | J4: No | M4: Wage Rate Year | N4: Wage Rate | O4: Wage Rate Fringe | P4: Wage Rate Total | Q4: Wage As of | R4: Wage Rate Next update | S4: Wage Rate List | Z4: ---- | AA4: ---- | AB4: ---- | AC4: ---- | AD4: ---- | AE4: ---- | AF4: ---- | AG4: ---- | AH4: ----
A5: What State is this project in? | B5: DC | C5: Project Type | D5: New Construction with deep shoring - small | E5: Days per Week | F5: 5 | G5: MBE or preference | H5: ---- | I5: % of people on Lifts we provide | J5: 1 | M5: NON-SCALE | N5: 30 | O5: 7.29 | P5: =+N5+O5 -> 37.29 | Q5: 46084 | R5: No | S5: =IF(M5="","",CONCATENATE(M5," - W: ($",N5," + F: $",O5,") = Total of $",P5)) -> NON-SCALE - W: ($30 + F: $7.29) = Total of $37.29 | Z5: Wilder Rodriguez | AA5: Wilder Rodriguez | AB5: Hassan Riaz | AC5: John Carlo Orpilla | AE5: Jonathan Bruce | AF5: Brian Angelo Limon | AG5: Hennan Berberio | AH5: Mark Chua
E6: Hours (per week) | F6: =+F4*F5 -> 40 | G6: Hours | I6: Lift cost average rental per 4 weeks | J6: 550 | L6: scale | M6: 2026 - DC/Federal in DC/CITIZEN | N6: 40.77 | O6: 20.17 | P6: =+N6+O6 -> 60.94 | Q6: 46074 | R6: Yes | S6: =IF(M6="","",CONCATENATE(M6," - W: ($",N6," + F: $",O6,") = Total of $",P6)) -> 2026 - DC/Federal in DC/CITIZEN - W: ($40.77 + F: $20.17) = Total of $60.94 | Z6: Bil Shams | AA6: Bil Shams | AB6: Mark Tan | AC6: Marc Maniago | AD6: Oliver Crucero | AE6: Maristella Malamug | AF6: Kevin Strauss | AG6: Ralph Resare | AH6: Hugh Belangel
E7: GSF of Building | G7: Number of personnel | H7: =ROUND(+J19/B12/(1950/12),2) -> 1.5 | I7: Total for lifts on this project | J7: =+Lift_percentage*Lift_cost*Project_Months*(4.4/4)*Average_no_people -> 1815 | L7: scale | M7: 2026 - Maryland/Federal | N7: 40.77 | O7: 20.42 | P7: =+N7+O7 -> 61.19 | Q7: 46074 | R7: Yes | S7: =IF(M7="","",CONCATENATE(M7," - W: ($",N7," + F: $",O7,") = Total of $",P7)) -> 2026 - Maryland/Federal - W: ($40.77 + F: $20.42) = Total of $61.19 | Z7: Mike Robberts | AA7: Mike Roberts | AB7: Rhal Dumol | AC7: Wesley Morris | AD7: Gerald Ordonez | AE7: Jeremee Camat | AG7: Joel Simplina | AH7: Junel Neri
A8: Is the job scale | B8: NON-SCALE - W: ($30 + F: $7.29) = Total of $37.29 | E8: Does O/CCIP cover WC? | F8: No | G8: Backcheck (hours) | H8: =ROUND(+B12*1950/12*H7,0) -> 488 | I8: Parking | L8: scale | M8: 2026 - Virginia | N8: 39.27 | O8: 18.67 | P8: =+N8+O8 -> 57.94 | Q8: 46074 | R8: Yes | S8: =IF(M8="","",CONCATENATE(M8," - W: ($",N8," + F: $",O8,") = Total of $",P8)) -> 2026 - Virginia - W: ($39.27 + F: $18.67) = Total of $57.94
E9: Wage | F9: =_xlfn.XLOOKUP(Project_Wage_Rate,Wage_Rate_List,Wage_Rate) -> 30 | G9: Material Escalation | I9: Parking | J9: Yes | L9: scale | M9: 2024 - MD Prevail | N9: 39.27 | O9: 19.42 | P9: =+N9+O9 -> 58.69 | Q9: 46074 | R9: Yes | S9: =IF(M9="","",CONCATENATE(M9," - W: ($",N9," + F: $",O9,") = Total of $",P9)) -> 2024 - MD Prevail - W: ($39.27 + F: $19.42) = Total of $58.69
A10: When will our work begin mm/YY (you can override) | B10: =EDATE(B2,B13) -> 46324 | C10: TOTAL BIDDING LABOR RATE | D10: =+labor_rate -> 51.7 | E10: Fringe | F10: =_xlfn.XLOOKUP(Project_Wage_Rate,Wage_Rate_List,Wage_Rate_Fringe) -> 7.29 | G10: Escalation on materials per Year | H10: 0.04 | I10: % of people on that will park | J10: 1 | L10: scale | M10: 2024 | N10: 40.02 | O10: 19.67 | P10: =+P11+0.75 -> 60.19 | Q10: 45931 | R10: Yes | S10: =IF(M10="","",CONCATENATE(M10," - W: ($",N10," + F: $",O10,") = Total of $",P10)) -> 2024 - W: ($40.02 + F: $19.67) = Total of $60.19
A11: When will our work end MM/YY (you can override) | B11: =EDATE(B10,B12-1) -> 46355 | C11: PARKING PER HOUR | D11: =IF(Parking="Yes",Parking_cost/Hours_per_day,0) -> 3.125 | E11: Totals | F11: =+F9+F10 -> 37.29 | G11: Total escalation based on year work will begin | H11: =(YEAR(B11)-YEAR(B2))*H10 -> 0 | I11: Parking Cost per Day - we reimburse | J11: 25 | L11: scale | M11: 2024 | N11: 40.02 | O11: 19.67 | P11: =+P12+0.75 -> 59.44 | Q11: 45931 | R11: Yes | S11: =IF(M11="","",CONCATENATE(M11," - W: ($",N11," + F: $",O11,") = Total of $",P11)) -> 2024 - W: ($40.02 + F: $19.67) = Total of $59.44
A12: Duration of Project - Months | B12: 2 | C12: LIFT PER HOUR | D12: =IF(Lifts_Needed="Yes",IFERROR(Total_Lift/Total_Hours,0),0) -> 0 | E12: Citizen Project | F12: No | G12: Sales Tax Applicable | H12: Yes | L12: scale | M12: 2023 | N12: 40.02 | O12: 19.67 | P12: =+P13+0.75 -> 58.69 | Q12: 45931 | R12: Yes | S12: =IF(M12="","",CONCATENATE(M12," - W: ($",N12," + F: $",O12,") = Total of $",P12)) -> 2023 - W: ($40.02 + F: $19.67) = Total of $58.69
A13: Start in # of months from bid | B13: 6 | C13: TOTAL LABOR PER HR WITH PARKING AND LIFTS | D13: =+D10+D11+D12 -> 54.825 | E13: Apprenticeable job | F13: Yes | G13: Sales Tax % | H13: =_xlfn.XLOOKUP(Project_State,Rate_State,Sales_Tax_by_state) -> 0.06 | L13: scale | M13: 2021 | N13: 39.27 | O13: 18.67 | P13: =+N13+O13 -> 57.94 | Q13: 45200 | R13: Yes | S13: =IF(M13="","",CONCATENATE(M13," - W: ($",N13," + F: $",O13,") = Total of $",P13)) -> 2021 - W: ($39.27 + F: $18.67) = Total of $57.94
A14: INPUT FIELD | L14: scale | M14: 2019 | N14: 38.01 | O14: 17.62 | P14: =+N14+O14 -> 55.63 | Q14: 44287 | R14: Yes | S14: =IF(M14="","",CONCATENATE(M14," - W: ($",N14," + F: $",O14,") = Total of $",P14)) -> 2019 - W: ($38.01 + F: $17.62) = Total of $55.63
A15: System | B15: Duct 1 | C15: Duct 2 | D15: Hydronic 1 | E15: Hydronic 2 | F15: Plumbing 1 | G15: Plumbing 2 | H15: VRF (only include if not in hydronic) | I15: Equipment (only include if not in MIKE) | J15: MIKE Estimate Totals | L15: scale | M15: 2017 | N15: 35.13 | O15: 16.22 | P15: =+N15+O15 -> 51.35 | Q15: 43556 | R15: Yes | S15: =IF(M15="","",CONCATENATE(M15," - W: ($",N15," + F: $",O15,") = Total of $",P15)) -> 2017 - W: ($35.13 + F: $16.22) = Total of $51.35
A16: Take off Personnel | B16: =IFERROR(_xlfn.XLOOKUP($F$2,Team_list,Duct_1),"") -> Marc Maniago | C16: =IFERROR(_xlfn.XLOOKUP($F$2,Team_list,Duct_2),"") -> Oliver Crucero | D16: =IFERROR(_xlfn.XLOOKUP(F$2,Team_list,Hydronic_1),"") -> Maristella Malamug | E16: =IFERROR(_xlfn.XLOOKUP(F$2,Team_list,Hydronic_2),"") -> Kevin Strauss | F16: =IFERROR(_xlfn.XLOOKUP(F$2,Team_list,Plumbing_1),"") -> Ralph Resare | G16: =IFERROR(_xlfn.XLOOKUP(F$2,Team_list,Plumbing_2),"") -> Hugh Belangel | L16: scale | M16: 2015 | N16: 35.03 | O16: 15.32 | P16: =+N16+O16 -> 50.35 | Q16: 42826 | R16: Yes | S16: =IF(M16="","",CONCATENATE(M16," - W: ($",N16," + F: $",O16,") = Total of $",P16)) -> 2015 - W: ($35.03 + F: $15.32) = Total of $50.35
A17: MIKE Estimate # | B17: 7969.02 | D17: 7969.04 | L17: scale | M17: 2013 | N17: 33.13 | O17: 13.6 | P17: =+N17+O17 -> 46.73 | Q17: 42095 | R17: Yes | S17: =IF(M17="","",CONCATENATE(M17," - W: ($",N17," + F: $",O17,") = Total of $",P17)) -> 2013 - W: ($33.13 + F: $13.6) = Total of $46.73
A18: Materials without escalation | B18: 3268.95 | D18: 5187.54 | J18: =IF(B$23="yes",B18,C18)+IF(D$23="yes",D18,E18)+IF(F$23="yes",F18,G18)+H18+I18 -> 8456.49 | S18: =IF(M18="","",CONCATENATE(M18," - W: ($",N18," + F: $",O18,") = Total of $",P18))
A19: Labor Hours | B19: 228.52 | D19: 259.07 | J19: =IF(B$23="yes",B19,C19)+IF(D$23="yes",D19,E19)+IF(F$23="yes",F19,G19)+H19+I19 -> 487.59 | S19: =IF(M19="","",CONCATENATE(M19," - W: ($",N19," + F: $",O19,") = Total of $",P19))
A20: TOTAL PRICE per MIKE | B20: 19515.92 | D20: 24321.76 | J20: =IF(B$23="yes",B20,C20)+IF(D$23="yes",D20,E20)+IF(F$23="yes",F20,G20)+H20+I20 -> 43837.68
A21: Quantity (LF/SF) | B21: 5455.98 | D21: 1129.84
A22: Quantity (This Sheet) | B22: =IF(B23="Yes",B21,C21) -> 5455.98 | D22: =IF(D23="Yes",D21,E21) -> 1129.84 | F22: =IF(F23="Yes",F21,G21) -> 0
A23: Who was used | B23: Yes | C23: No | D23: Yes | E23: No | F23: Yes | G23: No
A24: Labor per hour | B24: =IF(B19+C19=0,"",+Total_Wage-Parking_Per_Hour) -> 51.7 | D24: =IF(D19+E19=0,"",+Total_Wage-Parking_Per_Hour) -> 51.7 | F24: =IF(F19+G19=0,"",+Total_Wage-Parking_Per_Hour) | H24: =IF(H19=0,"",+Total_Wage-Parking_Per_Hour) | I24: =IF(I19=0,"",+Total_Wage-Parking_Per_Hour) | J24: =IF(J19=0,0,+Total_Wage-Parking_Per_Hour) -> 51.7
A25: Parking per hour | B25: =IF(Parking="Yes",Parking_Per_Hour,"") -> 3.125 | D25: =IF(Parking="Yes",Parking_Per_Hour,"") -> 3.125 | F25: =IF(Parking="Yes",Parking_Per_Hour,"") -> 3.125 | H25: =IF(Parking="Yes",Parking_Per_Hour,"") -> 3.125 | I25: =IF(Parking="Yes",Parking_Per_Hour,"") -> 3.125 | J25: =IF(J19=0,0,Parking_Per_Hour) -> 3.125
A26: Lifts per hour | B26: =IF(Lifts_Needed="Yes",Lifts_Per_Hour,"") | D26: =IF(Lifts_Needed="Yes",Lifts_Per_Hour,"") | F26: =IF(Lifts_Needed="Yes",Lifts_Per_Hour,"") | H26: =IF(Lifts_Needed="Yes",Lifts_Per_Hour,"") | I26: =IF(Lifts_Needed="Yes",Lifts_Per_Hour,"") | J26: =IF(J19=0,0,Lifts_Per_Hour) -> 0
A27: Materials/hour w escal+tax | B27: =IFERROR(IF(B23="Yes",B18/B19,C18/B19),"") -> 14.304875 | D27: =IFERROR(IF(D23="Yes",D18/D19,E18/D19),"") -> 20.0237 | F27: =IFERROR(IF(F23="Yes",F18/F19,G18/F19),"") | H27: =IFERROR(H18/H19,"") | I27: =IFERROR(I18/I19,"") | J27: =IFERROR(J18/J19,0) -> 17.343444
A28: Material Escalation | B28: =IFERROR(IF(B27="","",B27*Material_Escalation),"") -> 0 | D28: =IFERROR(IF(D27="","",D27*Material_Escalation),"") -> 0 | F28: =IFERROR(IF(F27="","",F27*Material_Escalation),"") | H28: =IFERROR(IF(H27="","",H27*Material_Escalation),"") | I28: =IFERROR(IF(I27="","",I27*Material_Escalation),"") | J28: =IFERROR(IF(J27="","",J27*Material_Escalation),"") -> 0
A29: Material Sales Tax | B29: =IFERROR((IF(B27="","",(B27+B28)*Sales_tax_percent)),"") -> 0.85829249 | D29: =IFERROR((IF(D27="","",(D27+D28)*Sales_tax_percent)),"") -> 1.201422 | F29: =IFERROR((IF(F27="","",(F27+F28)*Sales_tax_percent)),"") | H29: =IFERROR((IF(H27="","",(H27+H28)*Sales_tax_percent)),"") | I29: =IFERROR((IF(I27="","",(I27+I28)*Sales_tax_percent)),"") | J29: =IFERROR((IF(J27="","",(J27+J28)*Sales_tax_percent)),"") -> 1.0406067
A30: Total Cost per hour | B30: =IF(B24="","",IFERROR(+SUM(B24:C29),"")) -> 69.988167 | D30: =IF(D24="","",IFERROR(+SUM(D24:E29),"")) -> 76.050122 | F30: =IF(F24="","",IFERROR(+SUM(F24:G29),"")) | H30: =IF(H24="","",IFERROR(+SUM(H24:H29),"")) | I30: =IF(I24="","",IFERROR(+SUM(I24:I29),"")) | J30: =IF(J24="","",IFERROR(+SUM(J24:J29),"")) -> 73.209051
A31: Margin | B31: =IFERROR(+B30/(1-Margin)-B30,"") -> 23.329389 | D31: =IFERROR(+D30/(1-Margin)-D30,"") -> 25.350041 | F31: =IFERROR(+F30/(1-Margin)-F30,"") | H31: =IF(H25="","",IFERROR(+SUM(H25:H30),"")) -> 3.125 | I31: =IF(I25="","",IFERROR(+SUM(I25:I30),"")) -> 3.125 | J31: =IFERROR(+J30/(1-Margin)-J30,"") -> 24.403017
A32: Cost per hour with Margin | B32: =IFERROR(+B30+B31,"") -> 93.317556 | D32: =IFERROR(+D30+D31,"") -> 101.40016 | F32: =IFERROR(+F30+F31,"") | H32: =IFERROR(+H30/(1-Margin),"") | I32: =IFERROR(+I30/(1-Margin),"") | J32: =IFERROR(+J30+J31,"") -> 97.612068
A33: Cost based on math above | B33: =IFERROR(+(B30*B19)/(1-Margin),"") -> 21324.928 | D33: =IFERROR(+(D30*D19)/(1-Margin),"") -> 26269.74 | F33: =IFERROR(+(F30*F19)/(1-Margin),"") | H33: =IFERROR(+H32*H19,"") | I33: =IFERROR(+I32*I19,"") | J33: =IFERROR(ROUNDUP(+(J30*J19)/(1-Margin),-3),"") -> 48000
C36: Duct | D36: Hydronic | E36: Plumbing | F36: VRF | G36: Equipment | H36: Totals | I36: Cost per hour
A37: Labor Hours | C37: =IF(B23="Yes",B19,C19) -> 228.52 | D37: =IF(D23="Yes",D19,E19) -> 259.07 | E37: =IF(F23="Yes",F19,G19) -> 0 | F37: =+H19 -> 0 | G37: =+I19 -> 0 | H37: =SUM(C37:G37) -> 487.59
A38: Labor cost per hour | C38: =+Wage_Rate_Composite -> 51.7 | D38: =+Wage_Rate_Composite -> 51.7 | E38: =+Wage_Rate_Composite -> 51.7 | F38: =+Wage_Rate_Composite -> 51.7 | G38: =+Wage_Rate_Composite -> 51.7 | H38: =+Wage_Rate_Composite -> 51.7
A39: =+A25 -> Parking per hour | C39: =+Parking_Per_Hour -> 3.125 | D39: =+Parking_Per_Hour -> 3.125 | E39: =+Parking_Per_Hour -> 3.125 | F39: =+Parking_Per_Hour -> 3.125 | G39: =+Parking_Per_Hour -> 3.125 | H39: =+Parking_Per_Hour -> 3.125
A40: =+A26 -> Lifts per hour | C40: =+Lifts_Per_Hour -> 0 | D40: =+Lifts_Per_Hour -> 0 | E40: =+Lifts_Per_Hour -> 0 | F40: =+Lifts_Per_Hour -> 0 | G40: =+Lifts_Per_Hour -> 0 | H40: =+Lifts_Per_Hour -> 0
A41: Labor Total (no Margin) | C41: =IFERROR(+C37*SUM(C38:C40),"") -> 12528.609 | D41: =IFERROR(+D37*SUM(D38:D40),"") -> 14203.513 | E41: =IFERROR(+E37*SUM(E38:E40),"") -> 0 | F41: =IFERROR(+F37*SUM(F38:F40),"") -> 0 | G41: =IFERROR(+G37*SUM(G38:G40),"") -> 0 | H41: =IFERROR(+H37*SUM(H38:H40),"") -> 26732.122 | I41: =IFERROR(ROUNDUP(SUM(H38:H40)/H37,2),0) -> 0.12
A42: Materials (without escalations or profit) | C42: =IF(B23="Yes",B18,C18) -> 3268.95 | D42: =IF(D23="Yes",D18,E18) -> 5187.54 | E42: =IF(F23="Yes",F18,G18) -> 0 | F42: =+H18 -> 0 | G42: =+I18 -> 0 | H42: =SUM(C42:G42) -> 8456.49 | I42: =IFERROR(ROUNDUP((+SUM(H42:H44))/H37,2),0) -> 18.39
...

Sheet Budget
A1: ($) | B1: ($) | C1: ($) | D1: ($) | E1: ($) | F1: HRS | G1: LF | H1: ($) | I1: ($) | J1: ($) | K1: ($) | L1: ($) | M1: HRS | N1: SF | O1: ($) | P1: ($) | Q1: ($) | R1: ($) | S1: ($) | T1: HRS | U1: LF
A2: Hydronic Pipe - Total In House/Temp Labor Budget | B2: Hydronic Pipe - Total Material Budget | C2: Hydronic Pipe - Total Equipment Budget | D2: Hydronic Pipe - Total Bond Budget | E2: Hydronic Pipe - Total Other/Sub Budget | F2: Hydronic Pipe - Total Labor Manhours | G2: Hydronic Pipe - Quantity Pipe (LF) | H2: Duct - Total In House/Temp Labor Budget | I2: Duct - Total Material Budget | J2: Duct - Total Equipment Budget | K2: Duct - Total Bond Budget | L2: Duct - Total Other/Sub Budget | M2: Duct - Total Labor Manhours | N2: Duct - Quantity Duct (SF) | O2: Plumbing - Total In House/Temp Labor Budget | P2: Plumbing - Total Material Budget | Q2: Plumbing - Total Equipment Budget | R2: Plumbing - Total Bond Budget | S2: Plumbing - Total Other/Sub Budget | T2: Plumbing - Total Labor Manhours | U2: Plumbing - Quantity Pipe (LF) | V2: initial Labor Hour Budget | W2: Total Labor Hours Budget | X2: Total material Budget
A8: Budget
A9: Contract Price
A10: In House /Temp Labor
A11: Material Budget
A12: Equipment Budget
A13: Bond Cost
A14: OTH/Sub Budget
A15: Cost Estimate | C15: =SUM(C10:C14) -> 0

Sheet Labor Costs
A1: NOT FOR RELEASE - BIDDING ONLY - USE PM RATES | H1: WAGE RATE | I1: =IFERROR(labor_rate,"") -> 51.7
A2: Category | B2: Reg | C2: OT | D2: Qnt | E2: Extended | F2: Hrs | H2: Company | I2: =+'Base Bid'!D2 -> Goel Services, Inc.
A3: Asbestos Insulation Worker - Citizen/Prev Wage | B3: ='Labor Costs Worksheet'!H35 -> 47.69 | C3: ='Labor Costs Worksheet'!I35 -> 64.5 | D3: =IF(H4='Base Bid'!S5,"",IF(Project_Wage_Rate='Base Bid'!S5,"",No_Workers)) | E3: =IFERROR(IF(D3="","",+B3*40+(Hours_Per_week-40)*C3)*D3,"") | F3: =IF(D3="","",+D3*Hours_Per_week) | H3: Wage Rate | L3: =+B3 -> 47.69
A4: Asbestos Insulation Worker - Non Scale | B4: =+'Labor Costs Worksheet'!J35 -> 47.69 | C4: =+'Labor Costs Worksheet'!K35 -> 64.5 | D4: =IF(H4='Base Bid'!S5,(IF(Project_Wage_Rate='Base Bid'!S5,No_Workers,"")),"") -> 1 | E4: =IFERROR(IF(D4="","",+B4*40+(Hours_Per_week-40)*C4)*D4,"") -> 1907.6 | F4: =IF(D4="","",+D4*Hours_Per_week) -> 40 | H4: ='Base Bid'!$B$8 -> NON-SCALE - W: ($30 + F: $7.29) = Total of $37.29 | L4: =+B11 -> 35.75
A5: Working Asbestos Insulation Foreman (S5) | B5: ='Labor Costs Worksheet'!L35 -> 76.68 | C5: ='Labor Costs Worksheet'!M35 -> 104.91 | D5: =IF('Base Bid'!H8>5000,IF(Project_Wage_Rate='Base Bid'!S5,"",No_Foreman),"") | E5: =IFERROR(IF(D5="","",+B5*40+(Hours_Per_week-40)*C5)*D5,"") | F5: =IF(D5="","",+D5*Hours_Per_week) | L5: =+L3-L4 -> 11.94
A6: Working Asbestos Insulation Foreman (S4) | B6: ='Labor Costs Worksheet'!N35 -> 75.56 | C6: ='Labor Costs Worksheet'!O35 -> 103.79 | D6: =IFERROR(IF('Base Bid'!H8>4000,IF(Project_Wage_Rate='Base Bid'!S5,"",No_Foreman),"")-D5,"") | E6: =IFERROR(IF(D6="","",+B6*40+(Hours_Per_week-40)*C6)*D6,"") | F6: =IF(D6="","",+D6*Hours_Per_week) | H6: ='Base Bid'!A5 -> What State is this project in? | I6: ='Base Bid'!B5 -> DC | L6: =+L5*1950 -> 23283
A7: Working Asbestos Insulation Foreman (S3) | B7: ='Labor Costs Worksheet'!P35 -> 74.45 | C7: ='Labor Costs Worksheet'!Q35 -> 102.67 | D7: =IF('Base Bid'!H8<3999,IF(Project_Wage_Rate='Base Bid'!S5,"",No_Foreman),"") | E7: =IFERROR(IF(D7="","",+B7*40+(Hours_Per_week-40)*C7)*D7,"") | F7: =IF(D7="","",+D7*Hours_Per_week) | H7: ='Base Bid'!E12 -> Citizen Project | I7: ='Base Bid'!F12 -> No | L7: =20*L6 -> 465660
A8: Working Asbestos Insulation Foreman (S2) | B8: ='Labor Costs Worksheet'!R35 -> 50.12 | C8: ='Labor Costs Worksheet'!S35 -> 66.74 | D8: =IF(Project_Wage_Rate='Base Bid'!S5,No_Foreman,"") -> 1 | E8: =IFERROR(IF(D8="","",+B8*40+(Hours_Per_week-40)*C8)*D8,"") -> 2004.8 | F8: =IF(D8="","",+D8*Hours_Per_week) -> 40 | H8: ='Base Bid'!G7 -> Number of personnel | I8: ='Base Bid'!H7 -> 1.5
A9: Working Asbestos Insulation Foreman (S1) | B9: ='Labor Costs Worksheet'!T35 -> 49 | C9: ='Labor Costs Worksheet'!U35 -> 65.62 | E9: =IFERROR(IF(D9="","",+B9*40+(Hours_Per_week-40)*C9)*D9,"") | F9: =IF(D9="","",+D9*Hours_Per_week) | H9: ='Base Bid'!E6 -> Hours (per week) | I9: ='Base Bid'!F6 -> 40
A10: Safety Inspector (S5) | B10: ='Labor Costs Worksheet'!X35 -> 78.01 | C10: ='Labor Costs Worksheet'!Y35 -> 102.23 | E10: =IFERROR(IF(D10="","",+B10*40+(Hours_Per_week-40)*C10)*D10,"") | F10: =IF(D10="","",+D10*Hours_Per_week) | H10: Duration in Months | I10: ='Base Bid'!B12 -> 2
A11: Asbestos Apprentice Step 1 | B11: ='Labor Costs Worksheet'!Z35 -> 35.75 | C11: ='Labor Costs Worksheet'!AA35 -> 46.59 | E11: =IFERROR(IF(D11="","",+B11*40+(Hours_Per_week-40)*C11)*D11,"") | F11: =IF(D11="","",+D11*Hours_Per_week) | H11: ='Base Bid'!G8 -> Backcheck (hours) | I11: ='Base Bid'!H8 -> 488
A12: Asbestos Apprentice Step 2 | B12: ='Labor Costs Worksheet'!AB35 -> 36.14 | C12: ='Labor Costs Worksheet'!AC35 -> 47.17 | E12: =IFERROR(IF(D12="","",+B12*40+(Hours_Per_week-40)*C12)*D12,"") | F12: =IF(D12="","",+D12*Hours_Per_week) | H12: ='Base Bid'!E13 -> Apprenticeable job | I12: ='Base Bid'!F13 -> Yes
A13: Asbestos Apprentice Step 3 | B13: ='Labor Costs Worksheet'!AD35 -> 36.14 | C13: ='Labor Costs Worksheet'!AE35 -> 47.17 | D13: =No_Apprentices -> 0 | E13: =IFERROR(IF(D13="","",+B13*40+(Hours_Per_week-40)*C13)*D13,"") -> 0 | F13: =IF(D13="","",+D13*Hours_Per_week) -> 0
A14: Asbestos Apprentice Step 4 | B14: ='Labor Costs Worksheet'!AF35 -> 36.14 | C14: ='Labor Costs Worksheet'!AG35 -> 47.17 | E14: =IFERROR(IF(D14="","",+B14*40+(Hours_Per_week-40)*C14)*D14,"") | F14: =IF(D14="","",+D14*Hours_Per_week) | H14: ='Base Bid'!E8 -> Does O/CCIP cover WC? | I14: ='Base Bid'!F8 -> No
A15: Asbestos Apprentice Step 5 | B15: ='Labor Costs Worksheet'!AH35 -> 36.14 | C15: ='Labor Costs Worksheet'!AI35 -> 47.17 | E15: =IFERROR(IF(D15="","",+B15*40+(Hours_Per_week-40)*C15)*D15,"") | F15: =IF(D15="","",+D15*Hours_Per_week) | H15: Ratio 1: | I15: 2.5
A16: Asbestos Apprentice Step 6 | B16: =+'Labor Costs Worksheet'!AJ35 -> 36.14 | C16: =+'Labor Costs Worksheet'!AK35 -> 47.17 | E16: =IFERROR(IF(D16="","",+B16*40+(Hours_Per_week-40)*C16)*D16,"")
A17: Asbestos Apprentice Step 7 | B17: ='Labor Costs Worksheet'!AL35 -> 37.61 | C17: ='Labor Costs Worksheet'!AM35 -> 49.38 | E17: =IFERROR(IF(D17="","",+B17*40+(Hours_Per_week-40)*C17)*D17,"") | F17: =IF(D17="","",+D17*Hours_Per_week) | H17: Foreman | I17: 1
A18: Asbestos Apprentice Step 8 | B18: ='Labor Costs Worksheet'!AN35 -> 40.97 | C18: ='Labor Costs Worksheet'!AO35 -> 54.42 | E18: =IFERROR(IF(D18="","",+B18*40+(Hours_Per_week-40)*C18)*D18,"") | F18: =IF(D18="","",+D18*Hours_Per_week) | H18: Workers | I18: =IF(I8=0,1,ROUND(+I8-I17-I19,0)) -> 1
A19: Project Manager (S10) | B19: ='Labor Costs Worksheet'!V35 -> 83.55 | C19: ='Labor Costs Worksheet'!W35 -> 107.83 | D19: 0.1 | E19: =IFERROR(IF(D19="","",+B19*40+(Hours_Per_week-40)*C19)*D19,"") -> 334.2 | F19: =IF(D19="","",+D19*Hours_Per_week) -> 4 | H19: Apprentices | I19: =ROUND(+I8/(1+I15),0) -> 0
A20: =+'Labor Costs Worksheet'!AP4 -> Ops Manager | B20: ='Labor Costs Worksheet'!AP35 -> 83.61 | C20: ='Labor Costs Worksheet'!AQ35 -> 107.83 | D20: 0.1 | E20: =IFERROR(IF(D20="","",+B20*40+(Hours_Per_week-40)*C20)*D20,"") -> 334.44 | F20: =IF(D20="","",+D20*Hours_Per_week) -> 4
A21: Shop Foreman (S10) | B21: ='Labor Costs Worksheet'!AR35 -> 76.75 | C21: ='Labor Costs Worksheet'!AS35 -> 104.71 | D21: 0.05 | E21: =IFERROR(IF(D21="","",+B21*40+(Hours_Per_week-40)*C21)*D21,"") -> 153.5 | F21: =IF(D21="","",+D21*Hours_Per_week) -> 2
A22: Shop Insulator | B22: ='Labor Costs Worksheet'!AT35 -> 41.13 | C22: ='Labor Costs Worksheet'!AU35 -> 57.94 | D22: 0.2 | E22: =IFERROR(IF(D22="","",+B22*40+(Hours_Per_week-40)*C22)*D22,"") -> 329.04 | F22: =IF(D22="","",+D22*Hours_Per_week) -> 8 | H22: Wage | I22: =_xlfn.XLOOKUP(Project_Wage_Rate,Wage_Rate_List,Wage_Rate) -> 30
A23: Warehouseman | B23: ='Labor Costs Worksheet'!AV35 -> 32.76 | C23: ='Labor Costs Worksheet'!AW35 -> 44.49 | E23: =IFERROR(IF(D23="","",+B23*40+(Hours_Per_week-40)*C23)*D23,"") | F23: =IF(D23="","",+D23*Hours_Per_week) | H23: Fringe | I23: =_xlfn.XLOOKUP(Project_Wage_Rate,Wage_Rate_List,Wage_Rate_Fringe) -> 7.29
A24: Totals | D24: =SUM(D3:D23) -> 2.45 | E24: =SUM(E3:E23) -> 5063.58 | F24: =SUM(F3:F23) -> 98 | H24: Totals | I24: =_xlfn.XLOOKUP(Project_Wage_Rate,Wage_Rate_List,Wage_Rate_Total) -> 37.29
F25: =ROUNDUP(+E24/F24,1) -> 51.7

Sheet Labor Costs Worksheet
B1: =CONCATENATE(_xlfn.XLOOKUP('Labor Costs'!I$24,Wage_Rate_Total,Wage_Rate_Year)," - CBA Wage Rate") -> NON-SCALE - CBA Wage Rate | E1: COST OF LABOR CALCULATOR | BK1: Asbestos Insulation Worker | BM1: Working Asbestos Insulation Foreman (S5) | BO1: Project Manager (S10) | BQ1: Safety Inspector (S5) | BS1: Quality Control Inspector (S10) | BU1: Shop Foreman (S10) | BW1: Shop Insulator | BY1: Warehouseman
B2: Next rate increase on: | C2: =_xlfn.XLOOKUP(Project_Wage_Rate,Wage_Rate_List,Wage_As_of) -> 46084 | BF2: ---- | BH2: Hrs in Year (52 weeks x 40 hrs) | BJ2: Hrs | BK2: 2080 | BM2: 2080 | BO2: 2080 | BQ2: 2080 | BS2: 2080 | BU2: 2080 | BW2: 2080 | BY2: 2080
B3: Wage | C3: ='Labor Costs'!I22 -> 30 | BF3: YES | BH3: Paid Holiday ("+A") | BJ3: Hrs | BK3: -72 | BM3: -72 | BO3: -72 | BQ3: -72 | BS3: -72 | BU3: -72 | BW3: -72 | BY3: -72
B4: Fringe | C4: ='Labor Costs'!I23 -> 7.29 | E4: CBA Fringe | F4: 7.29 | H4: Asbestos Insulation Worker | J4: Non-Scale Worker | L4: Working Asbestos Insulation Foreman (S5) | N4: Working Asbestos Insulation Foreman (S4) | P4: Working Asbestos Insulation Foreman (S3) | R4: Working Asbestos Insulation Foreman (S2) | T4: Working Asbestos Insulation Foreman (S1) | V4: Project Manager (S10) | X4: Safety Inspector (S5) | Z4: Asbestos Apprentice Step 1 | AB4: Asbestos Apprentice Step 2 | AD4: Asbestos Apprentice Step 3 | AF4: Asbestos Apprentice Step 4 | AH4: Asbestos Apprentice Step 5 | AJ4: Asbestos Apprentice Step 6 | AL4: Asbestos Apprentice Step 7 | AN4: Asbestos Apprentice Step 8 | AP4: Ops Manager | AR4: Shop Foreman (S10) | AT4: Shop Insulator | AV4: Warehouseman | BF4: NO | BH4: Paid Sick, Personal Days | BJ4: Hrs | BK4: -56 | BM4: -56 | BO4: -56 | BQ4: -80 | BS4: -80 | BU4: -80 | BW4: -80 | BY4: -80
B5: Total | C5: ='Labor Costs'!I24 -> 37.29 | H5: 1 | J5: 1 | L5: 1 | N5: 1 | P5: 1 | R5: 1 | T5: 1 | V5: 1 | X5: 1 | Z5: 0.4 | AB5: 0.45 | AD5: 0.5 | AF5: 0.55 | AH5: 0.6 | AJ5: 0.65 | AL5: 0.7 | AN5: 0.8 | AP5: 1 | AR5: 1 | AT5: 1 | AV5: 1
H6: Reg | I6: OT | J6: Reg | K6: OT | L6: Reg | M6: OT | N6: Reg | O6: OT | P6: Reg | Q6: OT | R6: Reg | S6: OT | T6: Reg | U6: OT | V6: Reg | W6: OT | X6: Reg | Y6: OT | Z6: Reg | AA6: OT | AB6: Reg | AC6: OT | AD6: Reg | AE6: OT | AF6: Reg | AG6: OT | AH6: Reg | AI6: OT | AJ6: Reg | AK6: OT | AL6: Reg | AM6: OT | AN6: Reg | AO6: OT | AP6: Reg | AQ6: OT | AR6: Reg | AS6: OT | AT6: Reg | AU6: OT | AV6: Reg | AW6: OT | BH6: Hrs per year / Basis of Benefits | BJ6: Hrs | BK6: =SUM(BK2:BK4) -> 1952 | BM6: =SUM(BM2:BM4) -> 1952 | BO6: =SUM(BO2:BO4) -> 1952 | BQ6: =SUM(BQ2:BQ4) -> 1928 | BS6: =SUM(BS2:BS4) -> 1928 | BU6: =SUM(BU2:BU4) -> 1928 | BW6: =SUM(BW2:BW4) -> 1928 | BY6: =SUM(BY2:BY4) -> 1928
B7: ='Base Bid'!$B$8 -> NON-SCALE - W: ($30 + F: $7.29) = Total of $37.29 | H7: =+H8+H25 -> 37.29 | I7: =+I8+I25 -> 52.29 | J7: =+J8+J25 -> 37.29 | K7: =+K8+K25 -> 52.29 | L7: =+L8+L25 -> 63 | M7: =+M8+M25 -> 88.355 | N7: =+N8+N25 -> 62 | O7: =+O8+O25 -> 87.355 | ... AW7: =+AW8+AW25 -> 40.29
B8: WAGE - Taxable Wages & Taxable Fringes (See Below) | H8: =SUM(H9:H11) -> 30 | I8: =SUM(I9:I11) -> 45 | J8: =SUM(J9:J11) -> 30 | K8: =SUM(K9:K11) -> 45 | L8: =SUM(L9:L11) -> 55.71 | M8: =SUM(M9:M11) -> 81.065 | N8: =SUM(N9:N11) -> 54.71 | O8: =SUM(O9:O11) -> 80.065 | ... AW8: =SUM(AW9:AW11) -> 33
B9: Direct Labor Rate based on CBA (Actual for Individual or Average Rate for Typical Crew) | H9: =+'Labor Costs'!$I$22 -> 30 | I9: =+H9*1.5 -> 45 | J9: =+'Base Bid'!N5 -> 30 | K9: =+J9*1.5 -> 45 | L9: =IF(IF((Project_wage*L5+7.29)>26.96,Project_wage*L5,19.34)<Base_Rate_Wage,Base_Rate_Wage,IF((Project_wage*L5+7.29)>26.96,Project_wage*L5,19.34)) -> 50.71 | M9: =+L9*1.5 -> 76.065 | N9: =IF(IF((Project_wage*N5+7.29)>26.96,Project_wage*N5,19.34)<Base_Rate_Wage,Base_Rate_Wage,IF((Project_wage*N5+7.29)>26.96,Project_wage*N5,19.34)) -> 50.71 | O9: =+N9*1.5 -> 76.065 | P9: =IF(IF((Project_wage*P5+7.29)>26.96,Project_wage*P5,19.34)<Base_Rate_Wage,Base_Rate_Wage,IF((Project_wage*P5+7.29)>26.96,Project_wage*P5,19.34)) -> 50.71 | Q9: =+P9*1.5 -> 76.065 | R9: =IF((Project_wage*R5+7.29)>26.96,Project_wage*R5,19.34) -> 30 | S9: =+R9*1.5 -> 45 | T9: =IF((Project_wage*T5+7.29)>26.96,Project_wage*T5,19.34) -> 30 | U9: =+T9*1.5 -> 45 | V9: =IF(IF((Project_wage*V5+7.29)>26.96,Project_wage*V5,19.34)<Base_Rate_Wage,Base_Rate_Wage,IF((Project_wage*V5+7.29)>26.96,Project_wage*V5,19.34)) -> 50.71 | W9: =+V9*1.5 -> 76.065 | X9: =IF(IF((Project_wage*X5+7.29)>26.96,Project_wage*X5,19.34)<Base_Rate_Wage,Base_Rate_Wage,IF((Project_wage*X5+7.29)>26.96,Project_wage*X5,19.34)) -> 50.71 | Y9: =+X9*1.5 -> 76.065 | Z9: =IF((Project_wage*Z5+7.29)>26.96,Project_wage*Z5,19.34) -> 19.34 | AA9: =+Z9*1.5 -> 29.01 | AB9: =IF((Project_wage*AB$5+Wage_CBA_Fringe)>(19/0.965+Wage_CBA_Fringe),Project_wage*AB$5,19/0.965) -> 19.689119 | AC9: =+AB9*1.5 -> 29.533679 | AD9: =IF((Project_wage*AD$5+Wage_CBA_Fringe)>(19/0.965+Wage_CBA_Fringe),Project_wage*AD$5,19/0.965) -> 19.689119 | AE9: =+AD9*1.5 -> 29.533679 | AF9: =IF((Project_wage*AF$5+Wage_CBA_Fringe)>(19/0.965+Wage_CBA_Fringe),Project_wage*AF$5,19/0.965) -> 19.689119 | AG9: =+AF9*1.5 -> 29.533679 | AH9: =IF((Project_wage*AH$5+Wage_CBA_Fringe)>(19/0.965+Wage_CBA_Fringe),Project_wage*AH$5,19/0.965) -> 19.689119 | AI9: =+AH9*1.5 -> 29.533679 | AJ9: =IF((Project_wage*AJ$5+Wage_CBA_Fringe)>(19/0.965+Wage_CBA_Fringe),Project_wage*AJ$5,19/0.965) -> 19.689119 | AK9: =+AJ9*1.5 -> 29.533679 | AL9: =IF((Project_wage*AL$5+Wage_CBA_Fringe)>(19/0.965+Wage_CBA_Fringe),Project_wage*AL$5,19/0.965) -> 21 | AM9: =+AL9*1.5 -> 31.5 | AN9: =IF((Project_wage*AN$5+Wage_CBA_Fringe)>(19/0.965+Wage_CBA_Fringe),Project_wage*AN$5,19/0.965) -> 24 | AO9: =+AN9*1.5 -> 36 | AP9: =IF(IF((Project_wage*AP5+7.29)>26.96,Project_wage*AP5,19.34)<Base_Rate_Wage,Base_Rate_Wage,IF((Project_wage*AP5+7.29)>26.96,Project_wage*AP5,19.34)) -> 50.71 | AQ9: =+AP9*1.5 -> 76.065 | AR9: =IF(IF((Project_wage*AR5+7.29)>26.96,Project_wage*AR5,19.34)<Base_Rate_Wage,Base_Rate_Wage,IF((Project_wage*AR5+7.29)>26.96,Project_wage*AR5,19.34)) -> 50.71 | AS9: =+AR9*1.5 -> 76.065 | AT9: 30 | AU9: =+AT9*1.5 -> 45 | AV9: 22 | AW9: =+AV9*1.5 -> 33
A10: Annual Cap - First | B10: Supervisor/QC/Safety additional over wage | H10: 0 | J10: 0 | L10: 5 | M10: 5 | N10: 4 | O10: 4 | P10: 3 | Q10: 3 | R10: 2 | S10: 2 | T10: 1 | U10: 1 | V10: 10 | W10: 10 | X10: 5 | Y10: 5 | Z10: 0 | AB10: 0 | AD10: 0 | AF10: 0 | AH10: 0 | AJ10: 0 | AL10: 0 | AN10: 0 | AP10: 10 | AQ10: 10 | AR10: 10 | AS10: 10 | AT10: 0 | AV10: 0
B11: Cash as equivelent from unused Fringe Benefits (becomes taxable wages) | H11: =IF(+Project_Wage_and_Fringe*H5-Wage_CBA_Fringe-H9<0,0,+Project_Wage_and_Fringe*H5-Wage_CBA_Fringe-H9) -> 0 | I11: =+'Labor Costs'!$I$23-7.29 -> 0 | L11: =IF(+Project_Wage_and_Fringe*L5-Wage_CBA_Fringe-L9<0,0,+Project_Wage_and_Fringe*L5-Wage_CBA_Fringe-L9) -> 0 | M11: =+'Labor Costs'!$I$23-7.29 -> 0 | N11: =IF(+Project_Wage_and_Fringe*N5-Wage_CBA_Fringe-N9<0,0,+Project_Wage_and_Fringe*N5-Wage_CBA_Fringe-N9) -> 0 | O11: =+'Labor Costs'!$I$23-7.29 -> 0 | P11: =IF(+Project_Wage_and_Fringe*P5-Wage_CBA_Fringe-P9<0,0,+Project_Wage_and_Fringe*P5-Wage_CBA_Fringe-P9) -> 0 | Q11: =+'Labor Costs'!$I$23-7.29 -> 0 | R11: =IF(+Project_Wage_and_Fringe*R5-Wage_CBA_Fringe-R9<0,0,+Project_Wage_and_Fringe*R5-Wage_CBA_Fringe-R9) -> 0 | S11: =+'Labor Costs'!$I$23-7.29 -> 0 | T11: =IF(+Project_Wage_and_Fringe*T5-Wage_CBA_Fringe-T9<0,0,+Project_Wage_and_Fringe*T5-Wage_CBA_Fringe-T9) -> 0 | U11: =+'Labor Costs'!$I$23-7.29 -> 0 | V11: =IF(+Project_Wage_and_Fringe*V5-Wage_CBA_Fringe-V9<0,0,+Project_Wage_and_Fringe*V5-Wage_CBA_Fringe-V9) -> 0 | W11: =+'Labor Costs'!$I$23-7.29 -> 0 | X11: =IF(+Project_Wage_and_Fringe*X5-Wage_CBA_Fringe-X9<0,0,+Project_Wage_and_Fringe*X5-Wage_CBA_Fringe-X9) -> 0 | Y11: =+'Labor Costs'!$I$23-7.29 -> 0 | Z11: =IF(+Project_Wage_and_Fringe*Z5-Wage_CBA_Fringe-Z9<0,0,+Project_Wage_and_Fringe*Z5-Wage_CBA_Fringe-Z9) -> 0 | AA11: =+'Labor Costs'!$I$23-7.29 -> 0 | AB11: =IF(+Project_Wage_and_Fringe*AB5-Wage_CBA_Fringe-AB9<0,0,+Project_Wage_and_Fringe*AB5-Wage_CBA_Fringe-AB9) -> 0 | AC11: =+'Labor Costs'!$I$23-7.29 -> 0 | AD11: =IF(+Project_Wage_and_Fringe*AD5-Wage_CBA_Fringe-AD9<0,0,+Project_Wage_and_Fringe*AD5-Wage_CBA_Fringe-AD9) -> 0 | AE11: =+'Labor Costs'!$I$23-7.29 -> 0 | AF11: =IF(+Project_Wage_and_Fringe*AF5-Wage_CBA_Fringe-AF9<0,0,+Project_Wage_and_Fringe*AF5-Wage_CBA_Fringe-AF9) -> 0 | AG11: =+'Labor Costs'!$I$23-7.29 -> 0 | AH11: =IF(+Project_Wage_and_Fringe*AH5-Wage_CBA_Fringe-AH9<0,0,+Project_Wage_and_Fringe*AH5-Wage_CBA_Fringe-AH9) -> 0 | AI11: =+'Labor Costs'!$I$23-7.29 -> 0 | AJ11: =IF(+Project_Wage_and_Fringe*AJ5-Wage_CBA_Fringe-AJ9<0,0,+Project_Wage_and_Fringe*AJ5-Wage_CBA_Fringe-AJ9) -> 0 | AK11: =+'Labor Costs'!$I$23-7.29 -> 0 | AL11: =IF(+Project_Wage_and_Fringe*AL5-Wage_CBA_Fringe-AL9<0,0,+Project_Wage_and_Fringe*AL5-Wage_CBA_Fringe-AL9) -> 0 | AM11: =+'Labor Costs'!$I$23-7.29 -> 0 | AN11: =IF(+Project_Wage_and_Fringe*AN5-Wage_CBA_Fringe-AN9<0,0,+Project_Wage_and_Fringe*AN5-Wage_CBA_Fringe-AN9) -> 0 | AO11: =+'Labor Costs'!$I$23-7.29 -> 0 | AP11: =IF(+Project_Wage_and_Fringe*AP5-Wage_CBA_Fringe-AP9<0,0,+Project_Wage_and_Fringe*AP5-Wage_CBA_Fringe-AP9) -> 0 | AQ11: =+'Labor Costs'!$I$23-7.29 -> 0 | AR11: =IF(+Project_Wage_and_Fringe*AR5-Wage_CBA_Fringe-AR9<0,0,+Project_Wage_and_Fringe*AR5-Wage_CBA_Fringe-AR9) -> 0 | AS11: =+'Labor Costs'!$I$23-7.29 -> 0 | AT11: 0 | AU11: 0 | AV11: 0 | AW11: 0
B12: Payroll Taxes (See Below) - INDIRECT COSTS | H12: =SUM(H13:H24) -> 3.8374 | I12: =SUM(I13:I24) -> 5.6431 | J12: =SUM(J13:J24) -> 3.8374 | K12: =SUM(K13:K24) -> 5.6431 | L12: =SUM(L13:L24) -> 6.9323698 | M12: =SUM(M13:M24) -> 9.9846047 | N12: =SUM(N13:N24) -> 6.8119898 | O12: =SUM(O13:O24) -> 9.8642247 | ... AW12: =SUM(AW13:AW24) -> 4.19854
B13: Employer Labor Burdon Tax - Medicare Payroll Tax (FICA) | F13: Cap | G13: 0.009 | H13: =+H$8*$G13 -> 0.27 | I13: =+I$8*$G13 -> 0.405 | J13: =+J$8*$G13 -> 0.27 | K13: =+K$8*$G13 -> 0.405 | L13: =+L$8*$G13 -> 0.50139 | M13: =+M$8*$G13 -> 0.729585 | N13: =+N$8*$G13 -> 0.49239 | O13: =+O$8*$G13 -> 0.720585 | ... AW13: =+AW$8*$G13 -> 0.297
F14: 184500
B15: Employer Labor Burdon Tax - Federal Insurance Contributions Act (FICA) - Social Security Tax | F15: Cap | G15: =0.0765-0.009 -> 0.0675 | H15: =+H$8*$G15 -> 2.025 | I15: =+I$8*$G15 -> 3.0375 | J15: =+J$8*$G15 -> 2.025 | K15: =+K$8*$G15 -> 3.0375 | L15: =+L$8*$G15 -> 3.760425 | M15: =+M$8*$G15 -> 5.4718875 | N15: =+N$8*$G15 -> 3.692925 | O15: =+O$8*$G15 -> 5.4043875 | ... AW15: =+AW$8*$G15 -> 2.2275
F16: 184500
B17: Employer Labor Burdon Tax - State Unemployment Taxes (SUTA) (recognizing annual cap at 1000 hrs basis) | E17: Hours in equ per worker | F17: Cap | G17: {=_xlfn.IFS(Project_Company=Goel, _xlfn.XLOOKUP(Project_State, Rate_State, SUTA_GOEL_Rate,””), Project_Company=DCB, _xlfn.XLOOKUP(Project_State, Rate_State, SUTA__DCB__Rate,””), Project_Company=GoelDC, _xlfn.XLOOKUP(Project_State, Rate_State, SUTA_GOEL_DC__Rate,””),TRUE, "")} -> 0.033 | H17: =+SUTA/H8*H8*SUTA_RATE/Hours_per_worker -> 0.198 | I17: =+SUTA/I8*I8*SUTA_RATE/Hours_per_worker -> 0.198 | J17: =+SUTA/J8*J8*SUTA_RATE/Hours_per_worker -> 0.198 | K17: =+SUTA/K8*K8*SUTA_RATE/Hours_per_worker -> 0.198 | L17: =+SUTA/L8*L8*SUTA_RATE/Hours_per_worker -> 0.198 | M17: =+SUTA/M8*M8*SUTA_RATE/Hours_per_worker -> 0.198 | N17: =+SUTA/N8*N8*SUTA_RATE/Hours_per_worker -> 0.198 | O17: =+SUTA/O8*O8*SUTA_RATE/Hours_per_worker -> 0.198 | ... AW17: =+SUTA/AW8*AW8*SUTA_RATE/Hours_per_worker -> 0.198
E18: 1500 | F18: =_xlfn.XLOOKUP(Project_State,Rate_State,SUTA__CAP,"") -> 9000
B19: Employer Labor Burdon Tax - Federal Unemployment Tax Act (FUTA) (recognizing annual cap) | F19: Cap | G19: =_xlfn.XLOOKUP(Project_State,Rate_State,FUTA__Rate) -> 0.006 | H19: =+FUTA/H8*H8*FUTA_RATE/Hours_per_worker -> 0.028 | I19: =+FUTA/I8*I8*FUTA_RATE/Hours_per_worker -> 0.028 | J19: =+FUTA/J8*J8*FUTA_RATE/Hours_per_worker -> 0.028 | K19: =+FUTA/K8*K8*FUTA_RATE/Hours_per_worker -> 0.028 | L19: =+FUTA/L8*L8*FUTA_RATE/Hours_per_worker -> 0.028 | M19: =+FUTA/M8*M8*FUTA_RATE/Hours_per_worker -> 0.028 | N19: =+FUTA/N8*N8*FUTA_RATE/Hours_per_worker -> 0.028 | O19: =+FUTA/O8*O8*FUTA_RATE/Hours_per_worker -> 0.028 | ... AW19: =+FUTA/AW8*AW8*FUTA_RATE/Hours_per_worker -> 0.028
A20: 147000 | F20: 7000
A21: 147000 | B21: Worker's Compensation Insurance If CIPP/OCIP - Does WC coverage does not cover WC for PM, Ops, Safety, QC, and off site fabricators | F21: ='Base Bid'!E8 -> Does O/CCIP cover WC? | G21: =IF('Base Bid'!F8="NO",_xlfn.XLOOKUP(Project_State,Rate_State,WC_Insulation),"0") -> 0.04128 | H21: =IF('Base Bid'!$F8="NO",+H$8*$G21,0) -> 1.2384 | I21: =IF('Base Bid'!$F8="NO",+I$8*$G21,0) -> 1.8576 | J21: =IF('Base Bid'!$F8="NO",+J$8*$G21,0) -> 1.2384 | K21: =IF('Base Bid'!$F8="NO",+K$8*$G21,0) -> 1.8576 | L21: =IF('Base Bid'!$F8="NO",+L$8*$G21,0) -> 2.2997088 | M21: =IF('Base Bid'!$F8="NO",+M$8*$G21,0) -> 3.3463632 | N21: =IF('Base Bid'!$F8="NO",+N$8*$G21,0) -> 2.2584288 | O21: =IF('Base Bid'!$F8="NO",+O$8*$G21,0) -> 3.3050832 | ... U21: =IF('Base Bid'!$F8="NO",+U$8*$G21,0) -> 1.89888 | V21: =+V$8*$G21 -> 2.5061088 | W21: =+W$8*$G21 -> 3.5527632 | X21: =+X$8*$G21 -> 2.2997088 | Y21: =+Y$8*$G21 -> 3.3463632 | Z21: =IF('Base Bid'!$F8="NO",+Z$8*$G21,0) -> 0.7983552 | AA21: =IF('Base Bid'!$F8="NO",+AA$8*$G21,0) -> 1.1975328 | AB21: =IF('Base Bid'!$F8="NO",+AB$8*$G21,0) -> 0.81276684 | AC21: =IF('Base Bid'!$F8="NO",+AC$8*$G21,0) -> 1.2191503 | AD21: =IF('Base Bid'!$F8="NO",+AD$8*$G21,0) -> 0.81276684 | AE21: =IF('Base Bid'!$F8="NO",+AE$8*$G21,0) -> 1.2191503 | AF21: =IF('Base Bid'!$F8="NO",+AF$8*$G21,0) -> 0.81276684 | AG21: =IF('Base Bid'!$F8="NO",+AG$8*$G21,0) -> 1.2191503 | ... AO21: =IF('Base Bid'!$F8="NO",+AO$8*$G21,0) -> 1.48608 | AP21: =+AP$8*$G21 -> 2.5061088 | AQ21: =+AQ$8*$G21 -> 3.5527632 | AR21: =+AR$8*$G21 -> 2.5061088 | AS21: =+AS$8*$G21 -> 3.5527632 | AT21: =+AT$8*$G21 -> 1.2384 | AU21: =+AU$8*$G21 -> 1.8576 | AV21: =+AV$8*$G21 -> 0.90816 | AW21: =+AW$8*$G21 -> 1.36224
A22: 8500 | F22: ='Base Bid'!F8 -> No
A23: 7000 | B23: Employer Labor Burdon Tax - Paid Family Leave act (PFL) - Currently appplicable in DC and in MD effective 1-1-27. | F23: What State is this project in? | G23: =_xlfn.XLOOKUP(Project_State,Rate_State,PFL) -> 0.0026 | H23: =IFERROR(+H$8*$G23,0) -> 0.078 | I23: =IFERROR(+I$8*$G23,0) -> 0.117 | J23: =IFERROR(+J$8*$G23,0) -> 0.078 | K23: =IFERROR(+K$8*$G23,0) -> 0.117 | L23: =IFERROR(+L$8*$G23,0) -> 0.144846 | M23: =IFERROR(+M$8*$G23,0) -> 0.210769 | N23: =IFERROR(+N$8*$G23,0) -> 0.142246 | O23: =IFERROR(+O$8*$G23,0) -> 0.208169 | ... AW23: =IFERROR(+AW$8*$G23,0) -> 0.0858
F24: MD
B25: Untaxed Fringes - Exempt under IRS qualified tax exepmt fringe deductions (See Below) | H25: =SUM(H26:H28) -> 7.29 | I25: =SUM(I26:I28) -> 7.29 | J25: =SUM(J26:J28) -> 7.29 | K25: =SUM(K26:K28) -> 7.29 | L25: =SUM(L26:L28) -> 7.29 | M25: =SUM(M26:M28) -> 7.29 | N25: =SUM(N26:N28) -> 7.29 | O25: =SUM(O26:O28) -> 7.29 | ... AW25: =SUM(AW26:AW28) -> 7.29
B26: Union Savings Program or Company IRA (3% match of Wage) or both | H26: =0.25+0.07 -> 0.32 | I26: =+H26 -> 0.32 | J26: =0.25+0.07 -> 0.32 | K26: =+J26 -> 0.32 | L26: =0.25+0.07 -> 0.32 | M26: =+L26 -> 0.32 | N26: =0.25+0.07 -> 0.32 | O26: =+N26 -> 0.32 | P26: =0.25+0.07 -> 0.32 | Q26: =+P26 -> 0.32 | R26: =0.25+0.07 -> 0.32 | S26: =+R26 -> 0.32 | T26: =0.25+0.07 -> 0.32 | U26: =+T26 -> 0.32 | V26: =0.25+0.07+V8*0.03 -> 2.1413 | W26: =0.25+0.07+W8*0.03 -> 2.90195 | X26: =0.25+0.07+X8*0.03 -> 1.9913 | Y26: =0.25+0.07+Y8*0.03 -> 2.75195 | Z26: =0.25+0.07 -> 0.32 | AA26: =+Z26 -> 0.32 | AB26: =0.25+0.07 -> 0.32 | AC26: =+AB26 -> 0.32 | AD26: =0.25+0.07 -> 0.32 | AE26: =+AD26 -> 0.32 | AF26: =0.25+0.07 -> 0.32 | AG26: =+AF26 -> 0.32 | AH26: =0.25+0.07 -> 0.32 | AI26: =+AH26 -> 0.32 | AJ26: =0.25+0.07 -> 0.32 | AK26: =+AJ26 -> 0.32 | AL26: =0.25+0.07 -> 0.32 | AM26: =+AL26 -> 0.32 | AN26: =0.25+0.07 -> 0.32 | AO26: =+AN26 -> 0.32 | AP26: =0.25+0.07+AP8*0.03 -> 2.1413 | AQ26: =0.25+0.07+AQ8*0.03 -> 2.90195 | AR26: =0.25+0.07+AR8*0.03 -> 2.1413 | AS26: =0.25+0.07+AS8*0.03 -> 2.90195 | AT26: =0.25+0.07 -> 0.32 | AU26: =+AT26 -> 0.32 | AV26: =0.25+0.07 -> 0.32 | AW26: =+AV26 -> 0.32
B27: PPO Health, Vision and Dental Insurance - $2.40 per hr | H27: 2.4 | I27: =+H27 -> 2.4 | J27: 2.4 | K27: =+J27 -> 2.4 | L27: 2.4 | M27: =+L27 -> 2.4 | N27: 2.4 | O27: =+N27 -> 2.4 | P27: 2.4 | Q27: =+P27 -> 2.4 | R27: 2.4 | S27: =+R27 -> 2.4 | T27: 2.4 | U27: =+T27 -> 2.4 | V27: 2.4 | W27: =+V27 -> 2.4 | X27: 2.4 | Y27: =+X27 -> 2.4 | Z27: 2.4 | AA27: =+Z27 -> 2.4 | AB27: 2.4 | AC27: =+AB27 -> 2.4 | AD27: 2.4 | AE27: =+AD27 -> 2.4 | AF27: 2.4 | AG27: =+AF27 -> 2.4 | AH27: 2.4 | AI27: =+AH27 -> 2.4 | AJ27: 2.4 | AK27: =+AJ27 -> 2.4 | AL27: 2.4 | AM27: =+AL27 -> 2.4 | AN27: 2.4 | AO27: =+AN27 -> 2.4 | AP27: 2.4 | AQ27: =+AP27 -> 2.4 | AR27: 2.4 | AS27: =+AR27 -> 2.4 | AT27: 2.4 | AU27: =+AT27 -> 2.4 | AV27: 2.4 | AW27: =+AV27 -> 2.4
B28: Other Fringe Benefits in the Union Collective Bargaining Agreement | H28: =7.29-H27-H26 -> 4.57 | I28: =+H28 -> 4.57 | J28: =7.29-J27-J26 -> 4.57 | K28: =+J28 -> 4.57 | L28: =7.29-L27-L26 -> 4.57 | M28: =+L28 -> 4.57 | N28: =7.29-N27-N26 -> 4.57 | O28: =+N28 -> 4.57 | P28: =7.29-P27-P26 -> 4.57 | Q28: =+P28 -> 4.57 | R28: =7.29-R27-R26 -> 4.57 | S28: =+R28 -> 4.57 | T28: =7.29-T27-T26 -> 4.57 | U28: =+T28 -> 4.57 | V28: =7.29-V27-V26 -> 2.7487 | W28: =+V28 -> 2.7487 | X28: =7.29-X27-X26 -> 2.8987 | Y28: =+X28 -> 2.8987 | Z28: =7.29-Z27-Z26 -> 4.57 | AA28: =+Z28 -> 4.57 | AB28: =7.29-AB27-AB26 -> 4.57 | AC28: =+AB28 -> 4.57 | AD28: =7.29-AD27-AD26 -> 4.57 | AE28: =+AD28 -> 4.57 | AF28: =7.29-AF27-AF26 -> 4.57 | AG28: =+AF28 -> 4.57 | AH28: =7.29-AH27-AH26 -> 4.57 | AI28: =+AH28 -> 4.57 | AJ28: =7.29-AJ27-AJ26 -> 4.57 | AK28: =+AJ28 -> 4.57 | AL28: =7.29-AL27-AL26 -> 4.57 | AM28: =+AL28 -> 4.57 | AN28: =7.29-AN27-AN26 -> 4.57 | AO28: =+AN28 -> 4.57 | AP28: =7.29-AP27-AP26 -> 2.7487 | AQ28: =+AP28 -> 2.7487 | AR28: =7.29-AR27-AR26 -> 2.7487 | AS28: =+AR28 -> 2.7487 | AT28: =7.29-AT27-AT26 -> 4.57 | AU28: =+AT28 -> 4.57 | AV28: =7.29-AV27-AV26 -> 4.57 | AW28: =+AV28 -> 4.57
B29: Company Benefits (See Below) & Other | H29: =SUM(H30:H34) -> 6.5625 | I29: =SUM(I30:I34) -> 6.5625 | J29: =SUM(J30:J34) -> 6.5625 | K29: =SUM(K30:K34) -> 6.5625 | L29: =SUM(L30:L34) -> 6.7469262 | M29: =SUM(M30:M34) -> 6.5625 | N29: =SUM(N30:N34) -> 6.7469262 | O29: =SUM(O30:O34) -> 6.5625 | ... AW29: =SUM(AW30:AW34) -> 0
B30: Laptop Computer with Remote Accesss thru AWS Workspaces ($100 per month) | H30: 0 | J30: 0 | L30: 0 | N30: 0 | P30: 0 | R30: 0 | T30: 0 | V30: =100*12/BO6 -> 0.6147541 | X30: =100*12/BQ6 -> 0.62240664 | Z30: 0 | AB30: 0 | AD30: 0 | AF30: 0 | AH30: 0 | AJ30: 0 | AL30: 0 | AN30: 0 | AP30: =100*12/BS6 -> 0.62240664 | AR30: =100*12/BU6 -> 0.62240664 | AT30: 0 | AV30: 0
B31: Lifts | H31: =Lift_percentage*Lift_cost/160 -> 3.4375 | I31: =Lift_percentage*Lift_cost/160 -> 3.4375 | J31: =Lift_percentage*Lift_cost/160 -> 3.4375 | K31: =Lift_percentage*Lift_cost/160 -> 3.4375 | L31: =Lift_percentage*Lift_cost/160 -> 3.4375 | M31: =Lift_percentage*Lift_cost/160 -> 3.4375 | N31: =Lift_percentage*Lift_cost/160 -> 3.4375 | O31: =Lift_percentage*Lift_cost/160 -> 3.4375 | ... U31: =Lift_percentage*Lift_cost/160 -> 3.4375 | Z31: =Lift_percentage*Lift_cost/160 -> 3.4375 | AA31: =Lift_percentage*Lift_cost/160 -> 3.4375 | AB31: =Lift_percentage*Lift_cost/160 -> 3.4375 | AC31: =Lift_percentage*Lift_cost/160 -> 3.4375 | AD31: =Lift_percentage*Lift_cost/160 -> 3.4375 | AE31: =Lift_percentage*Lift_cost/160 -> 3.4375 | AF31: =Lift_percentage*Lift_cost/160 -> 3.4375 | AG31: =Lift_percentage*Lift_cost/160 -> 3.4375 | ... AO31: =Lift_percentage*Lift_cost/160 -> 3.4375
B32: Parking | H32: =IF(Parking="Yes",Parking_cost/8,"") -> 3.125 | I32: =IF(Parking="Yes",Parking_cost/8,"") -> 3.125 | J32: =IF(Parking="Yes",Parking_cost/8,"") -> 3.125 | K32: =IF(Parking="Yes",Parking_cost/8,"") -> 3.125 | L32: =IF(Parking="Yes",Parking_cost/8,"") -> 3.125 | M32: =IF(Parking="Yes",Parking_cost/8,"") -> 3.125 | N32: =IF(Parking="Yes",Parking_cost/8,"") -> 3.125 | O32: =IF(Parking="Yes",Parking_cost/8,"") -> 3.125 | ... AQ32: =IF(Parking="Yes",Parking_cost/8,"") -> 3.125
B33: Tablet ($30 per month) | H33: 0 | J33: 0 | L33: =30*12/BM6 -> 0.18442623 | N33: =30*12/BO6 -> 0.18442623 | P33: =30*12/BQ6 -> 0.18672199 | R33: =30*12/BS6 -> 0.18672199 | T33: =30*12/BU6 -> 0.18672199 | V33: =95*12/BO6 -> 0.58401639 | X33: =95*12/BQ6 -> 0.59128631 | Z33: 0 | AB33: 0 | AD33: 0 | AF33: 0 | AH33: 0 | AJ33: 0 | AL33: 0 | AN33: 0 | AP33: =95*12/BS6 -> 0.59128631 | AR33: =95*12/BU6 -> 0.59128631 | AT33: 0 | AV33: =95*12/BY6 -> 0.59128631
B34: Vehicle allowance ($600/Month) | H34: 0 | J34: 0 | L34: 0 | N34: 0 | P34: 0 | R34: 0 | T34: 0 | V34: =600*12/BO6 -> 3.6885246 | X34: =600*12/BQ6 -> 3.7344398 | Z34: 0 | AB34: 0 | AD34: 0 | AF34: 0 | AH34: 0 | AJ34: 0 | AL34: 0 | AN34: 0 | AP34: =600*12/BS6 -> 3.7344398 | AR34: 0 | AT34: 0 | AV34: 0
B35: Rate | H35: =ROUNDUP(+H$8+H$12+H$25+H$29,2) -> 47.69 | I35: =ROUNDUP(+I$8+I$12+I$25+I$29,2) -> 64.5 | J35: =ROUNDUP(+J$8+J$12+J$25+J$29,2) -> 47.69 | K35: =ROUNDUP(+K$8+K$12+K$25+K$29,2) -> 64.5 | L35: =ROUNDUP(+L$8+L$12+L$25+L$29,2) -> 76.68 | M35: =ROUNDUP(+M$8+M$12+M$25+M$29,2) -> 104.91 | N35: =ROUNDUP(+N$8+N$12+N$25+N$29,2) -> 75.56 | O35: =ROUNDUP(+O$8+O$12+O$25+O$29,2) -> 103.79 | ... AW35: =ROUNDUP(+AW$8+AW$12+AW$25+AW$29,2) -> 44.49
B36: Premium Over Time Rate | H36: =ROUNDUP(+#REF!-H35,2) -> #REF! | J36: =ROUNDUP(+#REF!-J35,2) -> #REF! | L36: =ROUNDUP(+#REF!-L35,2) -> #REF! | N36: =ROUNDUP(+#REF!-N35,2) -> #REF! | P36: =ROUNDUP(+#REF!-P35,2) -> #REF! | R36: =ROUNDUP(+#REF!-R35,2) -> #REF! | T36: =ROUNDUP(+#REF!-T35,2) -> #REF! | V36: =ROUNDUP(+#REF!-V35,2) -> #REF! | X36: =ROUNDUP(+#REF!-X35,2) -> #REF! | AP36: =ROUNDUP(+#REF!-AP35,2) -> #REF! | AR36: =ROUNDUP(+#REF!-AR35,2) -> #REF! | AT36: =ROUNDUP(+#REF!-AT35,2) -> #REF! | AV36: =ROUNDUP(+#REF!-AV35,2) -> #REF!
B37: Premium Double Time Rate | H37: =ROUNDUP(+#REF!-H35,2) -> #REF! | J37: =ROUNDUP(+#REF!-J35,2) -> #REF! | L37: =ROUNDUP(+#REF!-L35,2) -> #REF! | N37: =ROUNDUP(+#REF!-N35,2) -> #REF! | P37: =ROUNDUP(+#REF!-P35,2) -> #REF! | R37: =ROUNDUP(+#REF!-R35,2) -> #REF! | T37: =ROUNDUP(+#REF!-T35,2) -> #REF! | V37: =ROUNDUP(+#REF!-V35,2) -> #REF! | X37: =ROUNDUP(+#REF!-X35,2) -> #REF! | AP37: =ROUNDUP(+#REF!-AP35,2) -> #REF! | AR37: =ROUNDUP(+#REF!-AR35,2) -> #REF! | AT37: =ROUNDUP(+#REF!-AT35,2) -> #REF! | AV37: =ROUNDUP(+#REF!-AV35,2) -> #REF!
B39: General Liability Insurance due to Revenue Based Insurance due to Environmental Remediation Coverages ($0.00 if Covered by CCIP and it covers Environmental remediation and Polution Liability Policies ) | F39: Does O/CCIP cover GL Env Coverage? | G39: =IF(Startup!I56=FALSE,0.01343,"0") -> 0.01343 | H39: =IF($F40="No",+$G39*H35,0) -> 0.6404767 | J39: =IF($F40="No",+$G39*J35,0) -> 0.6404767 | L39: =IF($F40="No",+$G39*L35,0) -> 1.0298124 | N39: =IF($F40="No",+$G39*N35,0) -> 1.0147708 | P39: =IF($F40="No",+$G39*P35,0) -> 0.9998635 | R39: =IF($F40="No",+$G39*R35,0) -> 0.6731116 | T39: =IF($F40="No",+$G39*T35,0) -> 0.65807 | V39: =IF($F40="No",+$G39*V35,0) -> 1.1220765 | X39: =IF($F40="No",+$G39*X35,0) -> 1.0476743 | AP39: =IF($F40="No",+$G39*AP35,0) -> 1.1228823 | AR39: =IF($F40="No",+$G39*AR35,0) -> 1.0307525 | AT39: =IF($F40="No",+$G39*AT35,0) -> 0.5523759 | AV39: =IF($F40="No",+$G39*AV35,0) -> 0.4399668
F40: NO
B41: Total Rate per hr with GL | H41: =+H35+H39 -> 48.330477 | J41: =+J35+J39 -> 48.330477 | L41: =+L35+L39 -> 77.709812 | N41: =+N35+N39 -> 76.574771 | P41: =+P35+P39 -> 75.449864 | R41: =+R35+R39 -> 50.793112 | T41: =+T35+T39 -> 49.65807 | V41: =+V35+V39 -> 84.672077 | X41: =+X35+X39 -> 79.057674 | AP41: =+AP35+AP39 -> 84.732882 | AR41: =+AR35+AR39 -> 77.780753 | AT41: =+AT35+AT39 -> 41.682376 | AV41: =+AV35+AV39 -> 33.199967
...

Sheet Spec - HVAC Pipe
A1: HVAC Pipe | M1: HVAC_System | N1: HVAC_Systems_-_Abbreviations | O1: HVAC_Unit | P1: HVAC_Material_Code | Q1: HVAC_Material_Description | R1: HVAC_Area_Code | S1: HVAC_Area_Name | T1: HVAC_Thickness | U1: HVAC_Pipe_Size
A2: System | B2: Code | C2: Area | D2: Area Code | E2: Insulation | F2: Mike Code | G2: Unit | H2: Start Size | I2: End Size | J2: Thickness | K2: Extra Notes | M2: --- | N2: --- | O2: --- | P2: --- | Q2: --- | R2: --- | S2: --- | T2: --- | U2: ---
A3: AC Condensate | B3: {=_xlfn.XLOOKUP(A3,HVAC_System,HVAC_Systems___Abbreviations)} -> ACD | C3: All | D3: {=_xlfn.XLOOKUP(C3,HVAC_Area_Name,HVAC_Area_Code)} -> XX | E3: Fiberglass with ASJ | F3: {=_xlfn.XLOOKUP(E3,HVAC_Material_Description,HVAC_Material_Code)} -> FGA | G3: {=_xlfn.XLOOKUP(A3,HVAC_System,HVAC_Unit)} -> LF | H3: 0.25 | I3: 2 | J3: 1 | M3: AC Condensate | N3: ACD | O3: LF | P3: CAC | Q3: Cal Sil W/ Canvas | R3: XX | S3: All | T3: 0.25 | U3: 0.25
M4: Advanced Plant Water | N4: APW | O4: LF | P4: CAS | Q4: Cal Sil / Plain | R4: A | S4: Concealed | T4: 0.5 | U4: =+U3+0.125 -> 0.375
M5: Boiler Feed Water | N5: BFW | O5: LF | P5: CSA | Q5: Cal Sil w/ Aluminum | R5: E | S5: Exposed | T5: 0.75 | U5: =+U4+0.125 -> 0.5
M6: Breeching | N6: BRE | O6: LF | P6: CSP | Q6: Cal Sil W/ PVC | R6: M | S6: Mechanical | T6: 1 | U6: =+U5+0.125 -> 0.625
M7: Combustion Air | N7: CA | O7: LF | P7: CSS | Q7: Cal Sil W/ Stainless Steel | R7: O | S7: Outdoors | T7: 1.25 | U7: =+U6+0.125 -> 0.75
M8: Continuous Blowdown | N8: CBD | O8: LF | P8: DWP | Q8: Duct Wrap on Pipe | R8: G | S8: Underground | T8: 1.5 | U8: =+U7+0.125 -> 0.875
M9: Chilled Beam | N9: CHB | O9: LF | P9: FGA | Q9: Fiberglass with ASJ | R9: P | S9: Parking | T9: 1.75 | U9: =+U8+0.125 -> 1
M10: Chilled Water | N10: CHW | O10: LF | P10: FGC | Q10: Fiberglass w/ Canvas | R10: T | S10: Attic | T10: 2 | U10: =+U9+0.125 -> 1.125
M11: Condensor Water | N11: CON | O11: LF | P11: FGP | Q11: Fiberglass w/ PVC | R11: C | S11: Crawlspace | T11: 2.5 | U11: =+U10+0.125 -> 1.25
M12: Dual Temp Piping | N12: DTP | O12: LF | P12: FAL | Q12: Fiberglass w/ Aluminum | R12: W | S12: Wall | T12: 2.75 | U12: =+U11+0.125 -> 1.375
M13: Fuel Oil Piping | N13: FOL | O13: LF | P13: FGS | Q13: Fiberglass w/ Stainless Steel | R13: V | S13: Vertical | T13: 3 | U13: =+U12+0.125 -> 1.5
M14: Geothermal Piping | N14: GEO | O14: LF | P14: FGV | Q14: Fiberglass w/ VIC | R14: U | S14: Under Floor | T14: 3.5 | U14: =+U13+0.25 -> 1.75
M15: Generator Exhaust | N15: GEX | O15: LF | P15: FVC | Q15: Fiberglass w/ VIC / Canvas | R15: I | S15: Vault | T15: 4 | U15: =+U14+0.25 -> 2
M16: Glycol Piping | N16: GLY | O16: LF | P16: FVP | Q16: Fiberglass w/ VIC / PVC | R16: J | S16: Tunnel | T16: 5 | U16: =+U15+0.5 -> 2.5
M17: High Pressure Steam | N17: HPS | O17: LF | P17: FVA | Q17: Fiberglass w/ VIC / Aluminum | R17: K | S17: Trench | T17: 6 | U17: =+U16+0.5 -> 3
M18: Medium Pressure Steam | N18: MPS | O18: LF | P18: FVS | Q18: Fiberglass w/ VIC / Stainless | R18: L | S18: Lagging / Liner | T18: 7 | U18: =+U17+0.5 -> 3.5
M19: Low Pressure Steam | N19: LPS | O19: LF | P19: FLX | Q19: Armaflex | R19: H | S19: Heat Trace | T19: 8 | U19: =+U18+0.5 -> 4
M20: Steam Condensate | N20: SCD | O20: LF | P20: FLC | Q20: Armaflex W/ Canvas | R20: Q | S20: Concealed Double Layer | U20: =+U19+1 -> 5
M21: High Temp Steam Condensate | N21: HSC | O21: LF | P21: FLP | Q21: Armaflex W/ PVC | R21: D | S21: Exposed Double Layer | U21: =+U20+1 -> 6
M22: Medium Temp Steam Condensate | N22: MSC | O22: LF | P22: FLA | Q22: Armaflex W/ Aluminum | R22: S | S22: Mechanical Double Layer | U22: =+U21+1 -> 7
M23: Low Temp Steam Condensate | N23: LSC | O23: LF | P23: FLS | Q23: Armaflex W/ Stainless | R23: F | S23: Outdoor Double Layer | U23: =+U22+1 -> 8
M24: Heat Recovery | N24: HRE | O24: LF | P24: FMG | Q24: Foamglass | R24: B-06 | S24: Protection - Below - 06' ft. | U24: =+U23+1 -> 9
M25: Heat Traced Piping | N25: HTP | O25: LF | P25: FMA | Q25: Foamglass w/ Aluminum | R25: B-08 | S25: Protection - Below - 08' ft. | U25: =+U24+1 -> 10
M26: Hot Water Heating | N26: HWH | O26: LF | P26: FMP | Q26: Foamglass w/ PVC | R26: B-10 | S26: Protection - Below - 10' ft. | U26: =+U25+1 -> 11
M27: Pumped Condensate | N27: PC | O27: LF | P27: FMC | Q27: Foamglass w/ Canvas | R27: B-12 | S27: Protection - Below - 12' ft. | U27: =+U26+1 -> 12
M28: Primary Chilled Water | N28: PCH | O28: LF | P28: FMS | Q28: Foamglass w/ Stainless | R28: B-15 | S28: Protection - Below -15' ft.
M29: Process Cooling Water | N29: PCW | O29: LF | P29: FMV | Q29: Foamglass w/VIC
M30: Refrigerant | N30: REF | P30: FAV | Q30: Foamglass w/VIC/Aluminum
M31: Refrigerant Liquid | N31: RL | P31: FPV | Q31: Foamglass w/VIC/ PVC
M32: Refrigerant Suction | N32: RS | P32: FCV | Q32: Foamglass w/VIC/Canvas
M33: Refrigerant Gas | N33: RG | P33: FSV | Q33: Foamglass w/VIC/Stainless
M34: Secondary Chilled Water | N34: SCH | Q34: Polyiso
M35: Steam Vent | N35: STV
Q62: Phenolic

Sheet Spec - Plumbing
A1: Plumbing | M1: Plumbing_System | N1: Plumbing_Systems_-_Abbreviations | O1: Plumbing_Unit | P1: Plumbing_Material_Code | Q1: Plumbing_Material_Description | R1: Plumbing_Area_Code | S1: Plumbing_Area_Name | T1: Plumbing_Thickness | U1: Plumbing_Pipe_Size
A2: System | B2: Code | C2: Area | D2: Area Code | E2: Insulation | F2: Mike Code | G2: Unit | H2: Start Size | I2: End Size | J2: Thickness | K2: Extra Notes | M2: --- | N2: --- | O2: --- | P2: --- | Q2: --- | R2: --- | S2: --- | T2: --- | U2: ---
A3: Domestic Cold Water | B3: =_xlfn.XLOOKUP(A3,Plumbing_System,Plumbing_Systems___Abbreviations) -> DCW | C3: All | D3: =_xlfn.XLOOKUP(C3,Plumbing_Area_Name,Plumbing_Area_Code) -> XX | E3: Fiberglass with ASJ | F3: =_xlfn.XLOOKUP(E3,Plumbing_Material_Description,Plumbing_Material_Code) -> #VALUE! | G3: =_xlfn.XLOOKUP(A3,Plumbing_System,Plumbing_Unit) -> LF | H3: 0.25 | I3: 2 | J3: 1 | M3: AC Condensate | N3: ACD | O3: LF | P3: CAC | Q3: Cal Sil W/ Canvas | R3: XX | S3: All | T3: 0.25 | U3: 0.25
M4: Domestic Cold Water | N4: DCW | O4: LF | P4: CAS | Q4: Cal Sil / Plain | R4: A | S4: Concealed | T4: 0.5 | U4: =+U3+0.125 -> 0.375
M5: Domestic Hot Water | N5: DHW | O5: LF | P5: CSA | Q5: Cal Sil w/ Aluminum | R5: E | S5: Exposed | T5: 0.75 | U5: =+U4+0.125 -> 0.5
M6: Compressed Air | N6: CA | O6: LF | P6: CSP | Q6: Cal Sil W/ PVC | R6: M | S6: Mechanical | T6: 1 | U6: =+U5+0.125 -> 0.625
M7: Clear Water Waste | N7: CWW | O7: LF | P7: CSS | Q7: Cal Sil W/ Stainless Steel | R7: O | S7: Outdoors | T7: 1.25 | U7: =+U6+0.125 -> 0.75
M8: Fuel Oil Pipe | N8: FOL | O8: LF | P8: DWP | Q8: Duct Wrap on Pipe | R8: G | S8: Underground | T8: 1.5 | U8: =+U7+0.125 -> 0.875
M9: Garage Drain | N9: GD | O9: LF | P9: FGA | Q9: Fiberglass with ASJ | R9: P | S9: Parking | T9: 1.75 | U9: =+U8+0.125 -> 1
M10: High Purity Water | N10: HPW | O10: LF | P10: FGC | Q10: Fiberglass w/ Canvas | R10: T | S10: Attic | T10: 2 | U10: =+U9+0.125 -> 1.125
M11: Heat Traced Piping | N11: HTP | O11: LF | P11: FGP | Q11: Fiberglass w/ PVC | R11: C | S11: Crawlspace | T11: 2.5 | U11: =+U10+0.125 -> 1.25
M12: Laboratory Air | N12: LA | O12: LF | P12: FAL | Q12: Fiberglass w/ Aluminum | R12: W | S12: Wall | T12: 2.75 | U12: =+U11+0.125 -> 1.375
M13: Laboratory Domestic Cold Water | N13: LDC | O13: LF | P13: FGS | Q13: Fiberglass w/ Stainless Steel | R13: V | S13: Vertical | T13: 3 | U13: =+U12+0.125 -> 1.5
M14: Laboratory Domestic Hot Water | N14: LDH | O14: LF | P14: FGV | Q14: Fiberglass w/ VIC | R14: U | S14: Under Floor | T14: 3.5 | U14: =+U13+0.25 -> 1.75
M15: Make up Water | N15: MUW | O15: LF | P15: FVC | Q15: Fiberglass w/ VIC / Canvas | R15: I | S15: Vault | T15: 4 | U15: =+U14+0.25 -> 2
M16: Non Potable Water | N16: NPW | O16: LF | P16: FVP | Q16: Fiberglass w/ VIC / PVC | R16: J | S16: Tunnel | T16: 5 | U16: =+U15+0.5 -> 2.5
